tests/fixtures/coinbase_btc_uni_sequence.jsonl
{"channel":"l2_data","timestamp":"2026-09-08T12:00:00.000000001Z","sequence_num":0,"events":[{"type":"snapshot","product_id":"BTC-USD","updates":[{"side":"bid","price_level":"80000.00","new_quantity":"1.00"},{"side":"offer","price_level":"80001.00","new_quantity":"2.00"}]}]}
{"channel":"l2_data","timestamp":"2026-09-08T12:00:00.000000002Z","sequence_num":1,"events":[{"type":"snapshot","product_id":"UNI-USD","updates":[{"side":"bid","price_level":"4.570","new_quantity":"3.00"},{"side":"offer","price_level":"4.580","new_quantity":"4.00"}]}]}
{"channel":"heartbeats","timestamp":"2026-09-08T12:00:00.000000003Z","sequence_num":2,"events":[{"current_time":"2026-09-08T12:00:00.000000003Z","heartbeat_counter":"1"}]}
{"channel":"l2_data","timestamp":"2026-09-08T12:00:00.000000004Z","sequence_num":3,"events":[{"type":"update","product_id":"BTC-USD","updates":[{"side":"bid","price_level":"80000.00","new_quantity":"0"},{"side":"bid","price_level":"80002.00","new_quantity":"5.00"}]}]}
{"channel":"l2_data","timestamp":"2026-09-08T12:00:00.000000005Z","sequence_num":4,"events":[{"type":"update","product_id":"UNI-USD","updates":[{"side":"offer","price_level":"4.580","new_quantity":"0"},{"side":"offer","price_level":"4.590","new_quantity":"6.00"}]}]}
